#VRML_SIM R2023a utf8

EXTERNPROTO "https://raw.githubusercontent.com/cyberbotics/webots/R2023a/projects/objects/backgrounds/protos/TexturedBackground.proto"
EXTERNPROTO "https://raw.githubusercontent.com/cyberbotics/webots/R2023a/projects/objects/backgrounds/protos/TexturedBackgroundLight.proto"
EXTERNPROTO "https://raw.githubusercontent.com/cyberbotics/webots/R2023a/projects/objects/floors/protos/RectangleArena.proto"

WorldInfo {
  info [
    "Example use of a DistanceSensor device."
  ]
  title "Distance Sensor"
}
Viewpoint {
  orientation -0.06569151240484153 0.9694865168945396 0.2361789972831167 0.624188162625696
  position -0.8705858754690845 -0.2389182805272523 0.8479213909518833
  follow "MyBot:ds1"
}
TexturedBackground {
}
TexturedBackgroundLight {
}
RectangleArena {
}
DEF GREEN_BOX Solid {
  translation 0.25 0.09 0.05
  children [
    Shape {
      appearance PBRAppearance {
        baseColor 0 1 0
        roughness 0.2189099510000001
        metalness 0
      }
      geometry DEF BOX0 Box {
        size 0.1 0.23 0.1
      }
    }
  ]
  name "green box"
  boundingObject Shape {
    appearance PBRAppearance {
      roughness 1.1102230246251565e-16
      metalness 0
    }
    geometry USE BOX0
  }
}
DEF BLUE_BOX Solid {
  translation -0.27 -0.2 0.05
  rotation 0 0 1 0.31
  children [
    Shape {
      appearance PBRAppearance {
        baseColor 0 0 1
        roughness 0.519341125
        metalness 0
      }
      geometry DEF BOX1 Box {
        size 0.1 0.1 0.1
      }
    }
  ]
  name "blue box"
  boundingObject Shape {
    appearance PBRAppearance {
      roughness 1.1102230246251565e-16
      metalness 0
    }
    geometry USE BOX1
  }
}
DEF YELLOW_BOX Solid {
  translation -0.15 0.2 0.05
  rotation 0 0 1 0.4
  children [
    Shape {
      appearance PBRAppearance {
        baseColor 1 1 0
        roughness 0.03934117200000009
        metalness 0
      }
      geometry DEF BOX2 Box {
        size 0.3 0.05 0.1
      }
    }
  ]
  name "yellow box"
  boundingObject Shape {
    appearance PBRAppearance {
      roughness 1.1102230246251565e-16
      metalness 0
    }
    geometry USE BOX2
  }
}
DEF PINK_BOX Solid {
  translation 0.1 -0.42 0.05
  children [
    Shape {
      appearance PBRAppearance {
        baseColor 1 0.1 0.3
        roughness 0.16827074099999995
        metalness 0
      }
      geometry DEF BOX3 Box {
        size 0.08 0.15 0.1
      }
    }
  ]
  name "red box"
  boundingObject Shape {
    appearance PBRAppearance {
      roughness 1.1102230246251565e-16
      metalness 0
    }
    geometry USE BOX3
  }
}
DEF VIOLET_CYLINDER Solid {
  translation -0.12 -0.42 0.05
  rotation -0.4835807777315764 0.7292016648367512 0.484163777463612 1.88263
  children [
    DEF CYLINDER_SHAPE Shape {
      appearance PBRAppearance {
        baseColor 0.495903 0.078584 0.8
        roughness 1
        metalness 0
      }
      geometry Cylinder {
        height 0.1
        radius 0.05
      }
    }
  ]
  boundingObject USE CYLINDER_SHAPE
}
Robot {
  translation 0.27591774963094845 -0.1299661200224521 -0.00022713040773138932
  rotation -0.014230627289846991 0.01147452357006655 0.9998328983164023 1.784325176250731
  children [
    Transform {
      translation 0 0 0.0415
      rotation 0 0 1 -1.570796
      children [
        Shape {
          appearance PBRAppearance {
            baseColor 0.0820075 0.364731 0.8
            roughness 1
            metalness 0
          }
          geometry DEF BODY Cylinder {
            height 0.08
            radius 0.045
          }
        }
      ]
    }
    HingeJoint {
      jointParameters HingeJointParameters {
        position 129.0496745498473
        axis 0 1 0
        anchor 0 0 0.025
      }
      device [
        RotationalMotor {
          name "left wheel motor"
          consumptionFactor 70
        }
        PositionSensor {
          name "left wheel sensor"
        }
      ]
      endPoint Solid {
        translation 0 0.044999999999999984 0.025
        rotation -0.7070722749494567 0.7070724595173509 -0.009865849678760353 3.1218616397151258
        children [
          DEF WHEEL Transform {
            rotation 0.577656895078166 0.5771968951617173 -0.5771968951617173 -2.093935
            children [
              Shape {
                appearance PBRAppearance {
                  baseColor 1 0 0
                  roughness 1
                  metalness 0
                }
                geometry Cylinder {
                  height 0.01
                  radius 0.025
                }
              }
            ]
          }
        ]
        name "left wheel"
        boundingObject USE WHEEL
        physics DEF PHYSICS_WHEEL Physics {
          density -1
          mass 0.05
        }
        linearVelocity -6.0861874855828186e-09 2.749254015249613e-08 -3.481989310216703e-09
        angularVelocity -1.3397729351242024e-06 -2.9026713185128684e-07 -6.627480618972335e-10
      }
    }
    HingeJoint {
      jointParameters HingeJointParameters {
        position 17.30435604756286
        axis 0 1 0
        anchor 0 0 0.025
      }
      device [
        RotationalMotor {
          name "right wheel motor"
          consumptionFactor 70
        }
        PositionSensor {
          name "right wheel sensor"
        }
      ]
      endPoint Solid {
        translation 0 -0.04499999999999996 0.025
        rotation -0.546103807610959 0.5461037556226157 0.6352490215716093 4.273463524577018
        children [
          USE WHEEL
        ]
        name "right wheel"
        boundingObject USE WHEEL
        physics USE PHYSICS_WHEEL
        linearVelocity -5.838443702765695e-09 2.754444979345683e-08 -3.482483421635155e-09
        angularVelocity -1.3397663082548828e-06 -2.90280668126702e-07 5.605548371917882e-10
      }
    }
    DistanceSensor {
      translation 0.042 -0.02 0.063
      rotation -0.9626378392751118 0.19147896803009973 0.19147896803009973 -1.608865
      children [
        DEF SENSOR Transform {
          rotation 0.577656895078166 0.5771968951617173 -0.5771968951617173 -2.093935
          children [
            Shape {
              appearance PBRAppearance {
                baseColor 0.975691 0.981481 0.0252992
                roughness 1
                metalness 0
              }
              geometry Cylinder {
                height 0.004
                radius 0.008
              }
            }
          ]
        }
      ]
      name "ds0"
      lookupTable [
        0 1024 0
        0.02 1024 0.1
        0.08 0 0.3
      ]
      aperture 1
    }
    DistanceSensor {
      translation 0.02 -0.042 0.063
      rotation -0.7268313515069925 0.4856522348690052 0.4856522348690052 -1.884578
      children [
        USE SENSOR
      ]
      name "ds1"
      lookupTable [
        0 1024 0
        0.02 1024 0.1
        0.08 0 0.3
      ]
      aperture 1
    }
    DistanceSensor {
      translation 0.02 0.042 0.063
      rotation -0.7268278184260777 -0.4856548786751704 -0.4856548786751704 -1.884582
      children [
        USE SENSOR
      ]
      name "ds3"
      lookupTable [
        0 1024 0
        0.02 1024 0.1
        0.08 0 0.3
      ]
      aperture 1
    }
    DistanceSensor {
      translation 0.042 0.02 0.063
      rotation -0.9626362180015103 -0.19148304336382932 -0.19148304336382932 -1.608867
      children [
        USE SENSOR
      ]
      name "ds2"
      lookupTable [
        0 1024 0
        0.02 1024 0.1
        0.08 0 0.3
      ]
      aperture 1
    }
    DEF SMILE Transform {
      translation 0.036 0 0.025
      rotation 0.25056300542381216 -0.9351130202419243 -0.25056300542381216 1.637834
      children [
        Shape {
          appearance PBRAppearance {
            baseColor 0.721569 0.290196 0.290196
            roughness 1
            metalness 0
          }
          geometry Cylinder {
            height 0.018
            radius 0.009
            subdivision 3
          }
        }
      ]
    }
    Transform {
      rotation 0 0 1 3.14
      children [
        USE SMILE
      ]
    }
  ]
  name "MyBot"
  boundingObject Transform {
    translation 0 0 0.0415
    rotation 0 0 1 -1.570796
    children [
      USE BODY
    ]
  }
  physics Physics {
    density -1
    mass 0.5
  }
  controller "distance_sensor"
}
